<?xml version="1.0"?>
<sdf version="1.6">
 <model name="3dad_sl3">
   <link name="base">
    <!-- Offset the base by half the lenght of the cylinder -->
    <pose>0 0 0.0375 0 0 0</pose>
    <inertial>
      <mass>2</mass>
      <inertia>
        <ixx>0.0017375</ixx>
        <iyy>0.0017375</iyy>
        <izz>0.0016</izz>
        <ixy>0</ixy>
        <ixz>0</ixz>
        <iyz>0</iyz>
      </inertia>
    </inertial>

    <collision name="base_collision">
      <geometry>
        <cylinder>
          <radius>.04</radius>
          <length>.075</length>
        </cylinder>
      </geometry>
    </collision>

    <!-- The visual is mostly a copy of the collision -->
    <visual name="base_visual">
      <geometry>
        <cylinder>
          <radius>.04</radius>
          <length>.075</length>
        </cylinder>
      </geometry>
    </visual>
   </link>

  <link name="top">
    <!-- Offset the base by half the length of the cylinder -->
    <pose>0 0 0.1125 0 0 0</pose>
    <inertial>
      <mass>2</mass>
      <inertia>
        <ixx>0.0017375</ixx>
        <iyy>0.0017375</iyy>
        <izz>0.0016</izz>
        <ixy>0</ixy>
        <ixz>0</ixz>
        <iyz>0</iyz>
      </inertia>
    </inertial>

    <collision name="top_collision">
      <geometry>
        <cylinder>
          <radius>.04</radius>
          <length>.075</length>
        </cylinder>
      </geometry>
    </collision>

    <!-- The visual is mostly a copy of the collision -->
    <visual name="top_visual">
      <geometry>
        <cylinder>
          <radius>.04</radius>
          <length>.075</length>
        </cylinder>
      </geometry>
    </visual>
   </link>


  <link name="tray">

    <pose>0 0 0.1775 0 0 0</pose>
    <inertial>
      <mass>0.5</mass>
      <inertia>
        <ixx>0.00525520833</ixx>
        <iyy>0.00167083333</iyy>
        <izz>0.00691770833</izz>
        <ixy>0</ixy>
        <ixz>0</ixz>
        <iyz>0</iyz>
      </inertia>
    </inertial>

    <collision name="tray_collision">
      <geometry>
        <!--volume = 0.00071 cubic meters-->
        <box>
          <size>0.2 0.355 0.01</size>
        </box>
      </geometry>
    </collision>

    <!-- The visual is mostly a copy of the collision -->
    <visual name="tray_visual">
      <geometry>
        <box>
          <size>0.2 0.355 0.01</size>
        </box>
      </geometry>
    </visual>
   </link>


   <link name="3dad_sl3_link">
    <visual name="3dad_sl3_visual">
     <pose>0 0 0.2735 0 0 3.14159265359</pose>
     <geometry>
       <mesh> 
         <uri>model://3dad_sl3/mesh/3dad_sl3.dae</uri>
       </mesh>
     </geometry>
    </visual>
    <collision name="3dad_sl3_collision">
     <pose>0 0 0.2735 0 1.570796 1.570796</pose>
     <geometry>
       <cylinder>
         <radius>0.105</radius>
         <length>0.355</length>
       </cylinder>
     </geometry>
    </collision>
    <inertial>
     <mass>20.9</mass>
     <pose>0 0 0.2735 0 0 0</pose>
     <inertia>
       <ixx>0.27709917</ixx>
       <iyy>0.11521125</iyy>
       <izz>0.27709917</izz>
       <ixy>0</ixy>
       <ixz>0</ixz>
       <iyz>0</iyz>
     </inertia>
    </inertial>
    <sensor name="3d_pulse_lidar" type="gpu_ray">
      <plugin name="pulse_lidar_sensing" filename="libgazebo_ros_velodyne_gpu_laser.so">
          <topicName>nps_gazebo_ros_uw/pulse_lidar/points</topicName>
          <frameName>nps_gazebo_ros_uw/pulse_lidar_link</frameName>
          <min_intensity>0</min_intensity>
          <min_range>1</min_range>
          <max_range>20</max_range>
          <gaussianNoise>0.05</gaussianNoise>
      </plugin>

      <always_on>true</always_on>
      <!-- Position the ray sensor based on the specification. Also rotate
           it by 90 degrees around the X-axis so that the <horizontal> rays
           become vertical -->
      <pose>-0.014 0.2 0.28 0 0 1.570796</pose>

      <!-- Enable visualization to see the rays in the GUI -->
      <visualize>true</visualize>

      <!-- Set the update rate of the sensor -->
      <update_rate>40</update_rate>      
     <ray>
       <!-- The scan element contains the horizontal and vertical beams.-->
       <scan>
         <!-- The horizontal beams -->
         <horizontal>
           <!-- # of horizontal beams simulates a spinning beam -->
           <samples>145</samples>
           <!-- Resolution is multiplied by samples to determine number of
                simulated beams vs interpolated beams. See:
                http://sdformat.org/spec?ver=1.6&elem=sensor#horizontal_resolution
                -->
           <resolution>1</resolution>
           <!-- Minimum angle in radians -->
           <min_angle>-0.26179938779</min_angle>
           <!-- Maximum angle in radians -->
           <max_angle>0.26179938779</max_angle>
         </horizontal>

         <vertical>
           <samples>145</samples>
           <resolution>1</resolution>
           <min_angle>-0.26179938779</min_angle>
           <max_angle>0.26179938779</max_angle>
         </vertical>
       </scan>

       <!-- Range defines characteristics of an individual beam -->
       <range>
         <!-- Minimum distance of the beam in meters-->
         <min>1</min>
         <!-- Maximum distance of the beam in meters. 
              Should be between 2 and 45 meters, depending on visibility. -->
         <max>20</max>
         <!-- Linear resolution of each lidar ray. This _may_ refer to depth resolution. -->
         <resolution>0.1</resolution>
       </range>
       <noise>
         <!-- Use gaussian noise -->
         <type>gaussian</type>
         <mean>0.0</mean>
         <stddev>0.05</stddev>
       </noise>
      </ray>      
    </sensor>   
   </link>

   <!-- Each joint must have a unique name -->
   <joint type="revolute" name="base_top_joint">
     <!-- Position the joint at the bottom of the top link -->
     <pose>0 0 -0.0375 0 0 0</pose>
     <!-- Use the base link as the parent of the joint -->
     <parent>base</parent>
     <!-- Use the top link as the child of the joint -->
     <child>top</child>
     <!-- The axis defines the joint's degree of freedom -->
     <axis>
       <!-- Revolve around the z-axis -->
       <xyz>0 0 1</xyz>
       <!-- Limit refers to the range of motion of the joint -->
       <limit>
         <lower>-3.05432619099</lower>
         <upper>3.05432619099</upper>
       </limit>     
     </axis>
   </joint>

   <!-- Each joint must have a unique name -->
   <joint type="revolute" name="base_tray_joint">
     <!-- Position the joint at the bottom of the top link -->
     <pose>0 0 0 0 0 3.14159265359</pose>
     <!-- Use the base link as the parent of the joint -->
     <parent>top</parent>
     <!-- Use the top link as the child of the joint -->
     <child>tray</child>
     <!-- The axis defines the joint's degree of freedom -->
     <axis>
       <!-- Revolve around the y-axis -->
       <xyz>0 1 0</xyz>
       <!-- Limit refers to the range of motion of the joint -->
       <limit>
         <lower>-0.26179938779</lower>
         <upper>0.26179938779</upper>
       </limit>
     </axis>
   </joint>

   <!-- Each joint must have a unique name -->
   <joint type="fixed" name="tray_lidar_joint">
     <!-- Position the joint at the bottom of the top link -->
     <pose>0 0 0.19 0 0 0</pose>
     <!-- Use the base link as the parent of the joint -->
     <parent>tray</parent>
     <!-- Use the top link as the child of the joint -->
     <child>3dad_sl3_link</child>
   </joint>


  </model>
</sdf>
